<?xml version="1.0"?>
<robot name="rover1" xmlns:xacro="http://www.ros.org/wiki/xacro" >
    <!--<xacro:include filename="$(find rover1)/urdf/macros.xacro" />-->
   <xacro:property name="pi" value="3.14"/>
   <xacro:property name="m" value="4"/>
   <xacro:property name="r" value="0.24"/>
   <xacro:property name="h" value="0.1"/>

    <link name="base_link">
        <visual>
            <origin xyz="0.0 0.0 0.3"/>
            <geometry>
                <box size="0.8 0.6 0.3"/>
            </geometry>
            <material name="red">
                <color rgba="0.0 0.0 0.5 1.0"/>
            </material>
        </visual>

        <collision>
            <origin xyz="0.0 0.0 0.3"/>
            <geometry>
                <box size="0.8 0.6 0.3"/>
            </geometry>
        </collision>
            <inertial>
                <origin xyz="0.0 0.0 0.0" rpy="0 0 0"/>
                <mass value="50"/>
                <inertia ixx="0.0" ixy="0.0" ixz="0.0" iyy="0.0" iyz="0.0" izz="0.0" />
            </inertial>

    </link>

    <link name="wheel_dx">

        <inertial>
            <origin xyz="0.0 0.0 0.0" rpy="0.0 ${pi/2} ${pi/2}"/>
            <mass value="${m}"/>
            <inertia  ixx="${m*(3*r*r+h*h)/12}" ixy = "0" ixz = "0" iyy="${m*(3*r*r+h*h)/12}" iyz = "0" izz="${m*r*r/2}"/>
        </inertial>

        <visual>
            <origin xyz="0.0 0.0 0.0" rpy="0.0 ${pi/2} ${pi/2}"/>
            <geometry>
                <cylinder radius="${r}" length="${h}"/>
            </geometry>
            <material name="red">
                <color rgba="1.0 0.0 1.0 1.0"/>
            </material>
        </visual>

        <collision>
            <origin xyz="0.0 0.0 0.0" rpy="0.0 ${pi/2} ${pi/2}"/>
            <geometry>
                <cylinder radius="${r}" length="${h}"/>
            </geometry>
        </collision>

    </link>

    <link name="wheel_sx">

        <inertial>
            <origin xyz="0.0 0.0 0.0" rpy="0.0 ${pi/2} ${pi/2}"/>
            <mass value="${m}"/>
            <inertia  ixx="${m*(3*r*r+h*h)/12}" ixy = "0" ixz = "0" iyy="${m*(3*r*r+h*h)/12}" iyz = "0" izz="${m*r*r/2}"/>
        </inertial>

        <visual >
            <origin xyz="0 0.0 0.0" rpy="0.0 ${pi/2} ${pi/2}"/>
            <geometry>
                <cylinder radius="${r}" length="${h}"/>
            </geometry>
            <material name="red">
                <color rgba="1.0 0.0 1.0 1.0"/>
            </material>
        </visual>

        <collision>
            <origin xyz="0 0.0 0.0" rpy="0.0 ${pi/2} ${pi/2}"/>
            <geometry>
                <cylinder radius="${r}" length="${h}"/>
            </geometry>
        </collision>

    </link>


    <link name="sphere">
        <inertial>
            <origin xyz="0.0 0.0 0.0" rpy="0.0 0.0 0.0"/>
            <mass value="10"/>
            <inertia ixx="0.3" ixy="0.0" ixz="0.0" iyy="0.3" iyz="0.0" izz="0.2"/>
        </inertial>
        <visual >
            <origin xyz="0.0 0 0.0" rpy="0.0 0 0.0"/>
            <geometry>
                
                    <sphere radius="0.14"/>
                
            </geometry>
            <material name="red">
                <color rgba="1.0 0.0 0.6 1.0"/>
            </material>
        </visual>
        <collision>
            <origin xyz="0.0 0 0.0" rpy="0.0 0 0.0"/>
            <geometry>
                    <sphere radius="0.14"/>
            </geometry>
        </collision>
    </link>

    <gazebo reference="wheel_dx">
  <mu1 value="1.0"/>
  <mu2 value="1.0"/>
  <kp  value="10000000.0" />
  <kd  value="1.0" />
  <fdir1 value="1 0 0"/>
  <material>Gazebo/Black</material>
</gazebo>

<gazebo reference="wheel_sx">
  <mu1 value="1.0"/>
  <mu2 value="1.0"/>
  <kp  value="10000000.0" />
  <kd  value="1.0" />
  <fdir1 value="1 0 0"/>
  <material>Gazebo/Black</material>
</gazebo>


    <gazebo reference="sphere">
  <mu1>0.0</mu1>
  <mu2>0.0</mu2>
  <material>Gazebo/Red</material>
</gazebo>

    <joint name="joint_sphere" type="fixed">
        <parent link="base_link"/>
        <child link="sphere"/>
        <origin xyz="0.4 0.0 0.14" rpy="0.0 0.0 0.0"/>
    </joint>

    <joint name="motor_dx" type="continuous">
        <origin xyz="-0.2 0.35 0.24" rpy="0.0 0.0 0.0"/>
        <parent link="base_link"/>
        <child link="wheel_dx"/>
        <axis xyz="0 -1 0.0" rpy="0.0 0.0 0.0"/>
        <limit effort="100.0" velocity="100.0"/>
        <joint_properties damping="0.0" friction="0.0"/>
    </joint>

    <joint name="motor_sx" type="continuous">
        <origin xyz="-0.2 -0.35 0.24" rpy="0.0 0.0 0.0"/>
        <parent link="base_link"/>
        <child link="wheel_sx"/>
        <axis xyz="0.0 -1 0.0" rpy="0.0 0.0 0.0"/>
        <limit effort="100.0" velocity="100.0"/>
        <joint_properties damping="0.0" friction="0.0"/>
    </joint>

    <transmission name="motordx">
  <type>transmission_interface/SimpleTransmission</type>
  <joint name="motor_dx">
  <hardwareInterface>hardware_interface/EffortJointInterface</hardwareInterface>
  </joint>
  <actuator name="motor-dx">
    <hardwareInterface>hardware_interface/EffortJointInterface</hardwareInterface>
    <mechanicalReduction>10</mechanicalReduction>
  </actuator>
</transmission>

<transmission name="motorsx">
  <type>transmission_interface/SimpleTransmission</type>
  <joint name="motor_sx">
  <hardwareInterface>hardware_interface/EffortJointInterface</hardwareInterface>
  </joint>
  <actuator name="motor-sx">
    <hardwareInterface>hardware_interface/EffortJointInterface</hardwareInterface>
    <mechanicalReduction>10</mechanicalReduction>
  </actuator>
</transmission>

<gazebo>
  <plugin name="gazebo_ros_control" filename="libgazebo_ros_control.so">
    <robotNamespace>/myrover</robotNamespace>
    <legacyModeNS>true</legacyModeNS>
  </plugin>
</gazebo>

</robot>
